{
    "CVE_data_meta": {
        "ASSIGNER": "secalert@redhat.com",
        "ID": "CVE-2013-4260",
        "STATE": "PUBLIC"
    },
    "affects": {
        "vendor": {
            "vendor_data": [
                {
                    "product": {
                        "product_data": [
                            {
                                "product_name": "n/a",
                                "version": {
                                    "version_data": [
                                        {
                                            "version_value": "n/a"
                                        }
                                    ]
                                }
                            }
                        ]
                    },
                    "vendor_name": "n/a"
                }
            ]
        }
    },
    "data_format": "MITRE",
    "data_type": "CVE",
    "data_version": "4.0",
    "description": {
        "description_data": [
            {
                "lang": "eng",
                "value": "lib/ansible/playbook/__init__.py in Ansible 1.2.x before 1.2.3, when playbook does not run due to an error, allows local users to overwrite arbitrary files via a symlink attack on a retry file with a predictable name in /var/tmp/ansible/."
            }
        ]
    },
    "problemtype": {
        "problemtype_data": [
            {
                "description": [
                    {
                        "lang": "eng",
                        "value": "n/a"
                    }
                ]
            }
        ]
    },
    "references": {
        "reference_data": [
            {
                "name": "https://groups.google.com/forum/#!topic/ansible-project/UVDYW0HGcNg",
                "refsource": "CONFIRM",
                "url": "https://groups.google.com/forum/#!topic/ansible-project/UVDYW0HGcNg"
            },
            {
                "name": "https://bugzilla.redhat.com/show_bug.cgi?id=998227",
                "refsource": "CONFIRM",
                "url": "https://bugzilla.redhat.com/show_bug.cgi?id=998227"
            },
            {
                "name": "ansible-cve20134260-symlink(86898)",
                "refsource": "XF",
                "url": "https://exchange.xforce.ibmcloud.com/vulnerabilities/86898"
            },
            {
                "name": "http://www.ansible.com/security",
                "refsource": "CONFIRM",
                "url": "http://www.ansible.com/security"
            }
        ]
    }
}